<?xml version="1.0" encoding="utf-8"?>
<!-- =================================================================================== -->
<!-- |    This document was autogenerated by xacro from robot_description.urdf.xacro   | -->
<!-- |    EDITING THIS FILE BY HAND IS NOT RECOMMENDED                                 | -->
<!-- =================================================================================== -->
<robot name="BOBBY" xmlns:xacro="https://www.ros.org/wiki/xacro">
  <material name="white">
    <color rgba="1 1 1 1"/>
  </material>
  <material name="black">
    <color rgba="0 0 0 1"/>
  </material>
  <material name="blue">
    <color rgba="0 0 0.8 1"/>
  </material>
  <material name="yellow">
    <color rgba="1 1 0 1"/>
  </material>
  <material name="green">
    <color rgba="0 1 0 1"/>
  </material>
  <!-- Design your robot here -->
  <link name="base_link">
    <visual>
      <geometry>
        <box size="0.6 0.6 0.2"/>
      </geometry>
      <origin xyz="0 0 +0.05"/>
    </visual>
    <collision>
      <geometry>
        <box size="0.6 0.6 0.2"/>
      </geometry>
    </collision>
    <inertial>
      <mass value="10"/>
      <inertia ixx="0.4" ixy="0.0" ixz="0.0" iyy="0.4" iyz="0.0" izz="0.2"/>
    </inertial>
  </link>
  <link name="right_leg">
    <visual>
      <geometry>
        <cylinder length="0.2" radius="0.1"/>
      </geometry>
      <origin rpy="0 1.57075 0" xyz="0 0 0"/>
    </visual>
    <collision>
      <geometry>
        <cylinder length="0.2" radius="0.1"/>
      </geometry>
    </collision>
    <inertial>
      <mass value="1"/>
      <inertia ixx="0.4" ixy="0.0" ixz="0.0" iyy="1.57" iyz="0.0" izz="0.2"/>
    </inertial>
  </link>
  <joint name="base_to_right_leg" type="continuous">
    <axis xyz="1 0 0"/>
    <parent link="base_link"/>
    <child link="right_leg"/>
    <origin xyz="0.2 0.22 0.00"/>
  </joint>
  <link name="left_leg">
    <visual>
      <geometry>
        <cylinder length="0.2" radius="0.1"/>
      </geometry>
      <origin rpy="0 1.57075 0" xyz="0 0 0"/>
    </visual>
    <collision>
      <geometry>
        <cylinder length="0.2" radius="0.1"/>
      </geometry>
    </collision>
    <inertial>
      <mass value="1"/>
      <inertia ixx="0.4" ixy="0.0" ixz="0.0" iyy="1.57" iyz="0.0" izz="0.2"/>
    </inertial>
  </link>
  <joint name="base_to_left_leg" type="continuous">
    <parent link="base_link"/>
    <child link="left_leg"/>
    <axis xyz="1 0 0"/>
    <origin xyz="-0.2 0.22 0.00"/>
  </joint>
  <link name="sphere">
    <visual>
      <geometry>
        <sphere radius="0.1"/>
      </geometry>
    </visual>
    <collision>
      <geometry>
        <sphere radius="0.1"/>
      </geometry>
    </collision>
    <inertial>
      <mass value="1"/>
      <inertia ixx="0.4" ixy="0.0" ixz="0.0" iyy="0.4" iyz="0.0" izz="0.2"/>
    </inertial>
  </link>
  <joint name="base_to_sphere" type="continuous">
    <parent link="base_link"/>
    <child link="sphere"/>
    <axis xyz="1 0 0"/>
    <origin xyz="0 -0.22 -0.02"/>
  </joint>
  <!-- Below you will find samples of gazebo plugins you may want to use. -->
  <!-- These should be adapted to your robot's design -->
  <gazebo reference="YOUR_SENSOR_LINK">
    <sensor name="laser_right" type="ray">
      <pose>0 0 0 0 0 0</pose>
      <ray>
        <scan>
          <horizontal>
            <samples>13</samples>
            <resolution>1</resolution>
            <min_angle>-1.571</min_angle>
            <max_angle>1.571</max_angle>
          </horizontal>
        </scan>
        <range>
          <!-- You can edit adapt these to your robot's size -->
          <min>0.0005</min>
          <max>0.04</max>
          <resolution>0.0001</resolution>
        </range>
      </ray>
      <plugin filename="libgazebo_ros_laser.so" name="laser">
        <topicName>YOUR_ROBOT_LASER/scan</topicName>
        <frameName>YOUR_ROBOT_LASER_LINK</frameName>
      </plugin>
      <always_on>1</always_on>
      <update_rate>10</update_rate>
      <visualize>true</visualize>
    </sensor>
  </gazebo>
  <gazebo>
    <plugin filename="libgazebo_ros_diff_drive.so" name="differential_drive_controller">
      <alwaysOn>true</alwaysOn>
      <updateRate>20</updateRate>
      <leftJoint>base_to_left_leg</leftJoint>
      <rightJoint>base_to_right_leg</rightJoint>
      <wheelSeparation>0.6</wheelSeparation>
      <wheelDiameter>0.2</wheelDiameter>
      <wheelTorque>20</wheelTorque>
      <commandTopic>cmd_vel</commandTopic>
      <odometryTopic>odom</odometryTopic>
      <odometryFrame>odom</odometryFrame>
      <robotBaseFrame>base_link</robotBaseFrame>
    </plugin>
  </gazebo>
</robot>

